Workbook

Sheet Input
A1: LNG 탱크 BOR 예측 모델 — 입력 조건
A2: 항목 | B2: 값 | C2: 단위 | D2: 비고
A3: ▶ 탱크 기하 조건 | F3: ▶ 탱크 형상(고정) 및 사양 정보
A4: 탱크 내경 (직경) [m] | B4: 4 | C4: m | D4: 원통형 가정
A5: 탱크 길이 (원통부) [m] | B5: 10 | C5: m | G5: 원통형 LNG 탱크 (고정)
A6: LNG 충전율 [%] | B6: 90 | C6: % | D6: 0~100
A7: 탱크 내부 체적 [m³] | B7: =PI()*(B4/2)^2*B5+(4/3)*PI()*(B4/2)^3 | C7: m³ | D7: 내경·길이로 자동 계산
A8: LNG 체적 [m³] | B8: =B7*B6/100 | C8: m³ | D8: 체적 × 충전율
A9: ▶ 운전 조건
A10: 탱크 내부 압력 [bar(a)] | B10: 1.13 | C10: bar(a) | D10: 절대압
A11: 외부(주위) 온도 [℃] | B11: 25 | C11: ℃ | F11: ■ 사양 패널 (셀 연동)
A12: ▶ 단열재 조건 | F12: 탱크 내경 | G12: =B4 | H12: m
A13: 단열재 종류 | B13: Perlite(진공) | C13: - | D13: 드롭다운 선택 | F13: 탱크 길이 | G13: =B5 | H13: m
A14: 단열재 두께 [m] | B14: 0.3 | C14: m | F14: 충전율 | G14: =B6 | H14: %
A15: 진공도 [Pa] | B15: 1 | C15: Pa | D15: 진공단열 시 적용 | F15: 탱크 내부 체적 | G15: =B7 | H15: m³
A16: ▶ 배관 조건 | F16: LNG 체적 | G16: =B8 | H16: m³
A17: 배관 보냉/진공 여부 | B17: 진공배관 | C17: - | D17: 드롭다운 선택 | F17: 내부 압력 | G17: =B10 | H17: bar(a)
A18: 배관 추가 열유입 비율 [%] | B18: 10 | C18: % | D18: 탱크 열유입 대비 | F18: 외부 온도 | G18: =B11 | H18: ℃
A19: ▶ 계측 조건 | F19: 단열재 종류 | G19: =B13 | H19: -
A20: 안정화 시간 [h] | B20: 12 | C20: h | D20: BOG 안정화 대기 시간 | F20: 단열재 두께 | G20: =B14 | H20: m
A21: BOG 계측 시간 [h] | B21: 1 | C21: h | D21: 실측 수집 시간 | F21: 진공도 | G21: =B15 | H21: Pa
A22: ▶ LNG 조성 (상위 3성분) | F22: 배관 보냉/진공 | G22: =B17 | H22: -
A23: 성분 이름 | B23: 몰분율 [mol%] | C23: 단위 | D23: 비고 | F23: 배관 열유입 비율 | G23: =B18 | H23: %
A24: Methane | B24: 90 | C24: mol% | D24: 주성분 | F24: 성분1 이름 | G24: =A24 | H24: -
A25: Ethane | B25: 7 | C25: mol% | F25: 성분1 몰분율 | G25: =B24 | H25: mol%
A26: Propane | B26: 3 | C26: mol% | D26: 합계 100% | F26: 성분2 이름 | G26: =A25 | H26: -
F27: 성분2 몰분율 | G27: =B25 | H27: mol%
F28: 성분3 이름 | G28: =A26 | H28: -
F29: 성분3 몰분율 | G29: =B26 | H29: mol%

Sheet PropertyDB
A1: LNG BOR 예측 모델 — 물성 데이터베이스 (2_물성DB)
A2: ■ 단열재 열전도율 (k값)
A3: 단열재 종류 | B3: 열전도율 k [W/m·K]
A4: Polyurethane Foam (PUF) | B4: 0.025
A5: Perlite(대기압) | B5: 0.04
A6: Perlite(진공) | B6: 0.0015
A7: MLI(다층진공단열) | B7: 0.0005
A8: Glass Wool | B8: 0.038
A9: Vacuum Panel | B9: 0.008
A11: ■ LNG 성분 물성 (비등점 기준 대표값)
A12: 성분 | B12: 분자량 [g/mol] | C12: 잠열 ΔHvap [kJ/kg] | D12: 액밀도 [kg/m³] | E12: 비등점 [℃] | F12: 비고
A13: Methane | B13: 16.04 | C13: 511 | D13: 422.6 | E13: -161.5 | F13: 주성분
A14: Ethane | B14: 30.07 | C14: 489 | D14: 544.1 | E14: -88.6
A15: Propane | B15: 44.1 | C15: 426 | D15: 581 | E15: -42.1
A16: Nitrogen | B16: 28.01 | C16: 199 | D16: 806.6 | E16: -195.8
A17: i-Butane | B17: 58.12 | C17: 366 | D17: 593.4 | E17: -11.7
A18: n-Butane | B18: 58.12 | C18: 385 | D18: 601.8 | E18: -0.5
A20: ■ 배관 보냉계수 (열유입 보정)
A21: 배관 상태 | B21: 열유입 계수
A22: 보냉없음 | B22: 1
A23: 일반보냉 | B23: 0.4
A24: 진공배관 | B24: 0.1

Sheet BOR_Calc
A1: LNG 탱크 BOR 예측 계산 시트 (정상상태 열전달 모델)
A2: 계산 항목 | B2: 값 | C2: 단위 | D2: 수식/비고
A3: ▶ 탱크 기하 계산
A4: 탱크 반지름 r [m] | B4: =Input!B4/2 | C4: m | D4: 직경 / 2
A5: 원통부 외면 표면적 [m²] | B5: =2*PI()*B4*Input!B5 | C5: m² | D5: 2π r L
A6: 양단 반구 표면적 [m²] | B6: =4*PI()*B4^2 | C6: m² | D6: 4π r² (양쪽 반구 합)
A7: 총 표면적 A [m²] | B7: =B5+B6 | C7: m² | D7: 원통 + 양단 반구
A8: 탱크 내부 체적 V [m³] | B8: =PI()*B4^2*Input!B5+(4/3)*PI()*B4^3 | C8: m³ | D8: π r² L + (4/3)π r³
A9: LNG 체적 V_LNG [m³] | B9: =B8*Input!B6/100 | C9: m³ | D9: V_tank × 충전율(%)
A10: ▶ 단열 열저항 계산
A11: 단열재 k값 (VLOOKUP) [W/m·K] | B11: =VLOOKUP(Input!B13,PropertyDB!A4:B9,2,FALSE) | C11: W/m·K | D11: 2_물성DB A4:B9 참조
A12: 진공보정계수 (고진공 시 keff 감소) | B12: =IF(Input!B15<10,0.7,IF(Input!B15<100,0.85,1.0)) | C12: - | D12: 진공도<10Pa→0.7, <100Pa→0.85, 대기→1.0
A13: 유효 열전도율 keff [W/m·K] | B13: =B11*B12 | C13: W/m·K | D13: k × 진공보정계수
A14: 열저항 R [K/W] | B14: =Input!B14/(B13*B7) | C14: K/W | D14: 두께 / (keff × A)
A15: ▶ LNG 조성 가중평균 물성 계산
A16: 성분1 잠열 [kJ/kg] | B16: =VLOOKUP(Input!A24,PropertyDB!A13:E18,3,FALSE) | C16: kJ/kg | D16: 2_물성DB A13:E18 참조
A17: 성분2 잠열 [kJ/kg] | B17: =VLOOKUP(Input!A25,PropertyDB!A13:E18,3,FALSE) | C17: kJ/kg
A18: 성분3 잠열 [kJ/kg] | B18: =VLOOKUP(Input!A26,PropertyDB!A13:E18,3,FALSE) | C18: kJ/kg
A19: 평균 잠열 ΔHvap [kJ/kg] | B19: =(B16*Input!B24+B17*Input!B25+B18*Input!B26)/(Input!B24+Input!B25+Input!B26) | C19: kJ/kg | D19: 몰분율 가중평균
A20: 성분1 액밀도 [kg/m³] | B20: =VLOOKUP(Input!A24,PropertyDB!A13:E18,4,FALSE) | C20: kg/m³
A21: 성분2 액밀도 [kg/m³] | B21: =VLOOKUP(Input!A25,PropertyDB!A13:E18,4,FALSE) | C21: kg/m³
A22: 성분3 액밀도 [kg/m³] | B22: =VLOOKUP(Input!A26,PropertyDB!A13:E18,4,FALSE) | C22: kg/m³
A23: 평균 밀도 ρ [kg/m³] | B23: =(B20*Input!B24+B21*Input!B25+B22*Input!B26)/(Input!B24+Input!B25+Input!B26) | C23: kg/m³ | D23: 몰분율 가중평균
A24: 성분1 비등점 [℃] | B24: =VLOOKUP(Input!A24,PropertyDB!A13:E18,5,FALSE) | C24: ℃
A25: 성분2 비등점 [℃] | B25: =VLOOKUP(Input!A25,PropertyDB!A13:E18,5,FALSE) | C25: ℃
A26: 성분3 비등점 [℃] | B26: =VLOOKUP(Input!A26,PropertyDB!A13:E18,5,FALSE) | C26: ℃
A27: 평균 비등점 T_bp [℃] | B27: =(B24*Input!B24+B25*Input!B25+B26*Input!B26)/(Input!B24+Input!B25+Input!B26) | C27: ℃ | D27: 몰분율 가중평균
A28: ▶ 압력 보정 계산
A29: 압력보정계수 | B29: =MAX(0.8,1-((Input!B10-1.013)*0.05)) | C29: - | D29: 압력↑→비등점↑→BOG↓ (근사, 최소 0.8)
A30: ▶ 열침투량 Q 계산
A31: 온도차 ΔT [K] | B31: =Input!B11-B27 | C31: K | D31: 외부온도 - LNG 평균비등점
A32: 탱크 열침투 Q_tank [W] | B32: =B31/B14 | C32: W | D32: ΔT / R
A33: 배관 보냉계수 (VLOOKUP) | B33: =VLOOKUP(Input!B17,PropertyDB!A22:B24,2,FALSE) | C33: - | D33: 2_물성DB A22:B24 참조
A34: 배관 열침투 Q_pipe [W] | B34: =B32*(Input!B18/100)*B33 | C34: W | D34: Q_tank × 배관비율 × 배관계수
A35: 총 열침투 Q_total [W] | B35: =B32+B34 | C35: W | D35: Q_tank + Q_pipe
A36: ▶ BOG / BOR 결과
A37: BOG 질량유량 [kg/s] | B37: =B35/(B19*1000) | C37: kg/s | D37: Q_total / ΔHvap[J/kg]
A38: BOG 일일 증발량 [kg/day] | B38: =B37*86400*B29 | C38: kg/day | D38: BOG유량 × 86400 × 압력보정
A39: LNG 총 질량 [kg] | B39: =B9*B23 | C39: kg | D39: V_LNG × 평균밀도
A40: ★ BOR [%/day] | B40: =B38/B39*100 | C40: %/day | D40: 최종 예측 BOR
...

Sheet Measure
A1: 실측 BOG → BOR 역산 및 예측 비교 (4_계측보정)
A2: 항목 | B2: 값 | C2: 단위 | D2: 비고
A3: ▶ 실측 BOG 입력
A4: 실측 BOG량 [kg] | B4: 0 | C4: kg | D4: ← 사용자 직접 입력 (계측 동안 수집량)
A5: 계측 시간 [h] | B5: =Input!B21 | C5: h | D5: 1_입력조건 참조
A6: ▶ 안정화 보정 및 실측 BOR 계산
A7: 안정화 보정계수 | B7: =IF(Input!B20<6,1.15,IF(Input!B20<12,1.05,1.0)) | C7: - | D7: 안정화<6h→1.15 / <12h→1.05 / ≥12h→1.0
A8: 실측 BOG [kg/h] | B8: =B4/B5*B7 | C8: kg/h | D8: 실측량 / 계측시간 × 보정계수
A9: 실측 BOG [kg/day] | B9: =B8*24 | C9: kg/day | D9: 시간당 × 24
A10: LNG 총 질량 [kg] | B10: =BOR_Calc!B39 | C10: kg | D10: 3_BOR계산 참조
A11: ★ 실측 BOR [%/day] | B11: =B9/B10*100 | C11: %/day | D11: 실측BOG일일 / LNG총질량 × 100
A12: ▶ 예측 BOR vs 실측 BOR 비교
A13: ★ 예측 BOR [%/day] | B13: =BOR_Calc!B40 | C13: %/day | D13: 3_BOR계산 최종 결과
A14: 오차율 [%] | B14: =(B11-B13)/B13*100 | C14: % | D14: (실측 - 예측) / 예측 × 100
A15: 판정 | B15: =IF(ABS(B14)<10,"✅ 양호","⚠ 재계측 권장") | C15: - | D15: 오차 10% 미만이면 양호
A17: 📌 주의: 이 모델은 정상상태(steady-state) 열전달 기반의 설계 예측용 모델입니다. 실측값과의 오차가 10% 이상이면 단열재 물성, 충전율, 탱크 형상 등 입력값을 재확인하거나 일사량, 지면 열전도 등 현장 조건을 추가 반영하세요.
